<?xml version="1.0"?>
<!--
  Butter Finger CAD model.

  GENERATED FILE. Do not edit by hand.
  Regenerate with: python3 scripts/generate_urdf.py

  Mesh frames, joint transforms, masses, and inertia tensors were exported
  from SolidWorks with SW2URDF on 2026-07-16. The SW2URDF zero-width limits
  were intentionally replaced with calibrated command limits from
  config/joints.yaml. The camera frame uses the recorded optical-center
  transform from config/geometry.yaml; its intrinsics remain provisional.
  Load with useFixedBase=True.
-->
<robot name="butter_finger">
  <material name="cad_grey">
    <color rgba="0.75 0.75 0.75 1"/>
  </material>

  <link name="base_link">
    <visual>
      <origin xyz="0 0 0" rpy="0 0 0"/>
      <geometry>
        <mesh filename="meshes/base_link.stl"/>
      </geometry>
      <material name="cad_grey"/>
    </visual>
    <collision>
      <origin xyz="0 0 0" rpy="0 0 0"/>
      <geometry>
        <mesh filename="meshes/base_link.stl"/>
      </geometry>
    </collision>
    <inertial>
      <origin xyz="4.44769784005585e-06 -0.00272368672308015 -3.52117050677521e-05" rpy="0 0 0"/>
      <mass value="0.117956347342971"/>
      <inertia ixx="5.16379995080435e-05" ixy="-7.1735716911798e-12" ixz="-6.26544070809245e-09" iyy="8.54863593083873e-05" iyz="1.98513945412824e-07" izz="5.24951696421001e-05"/>
    </inertial>
  </link>

  <link name="turret_link">
    <visual>
      <origin xyz="0 0 0" rpy="0 0 0"/>
      <geometry>
        <mesh filename="meshes/turret_link.stl"/>
      </geometry>
      <material name="cad_grey"/>
    </visual>
    <collision>
      <origin xyz="0 0 0" rpy="0 0 0"/>
      <geometry>
        <mesh filename="meshes/turret_link.stl"/>
      </geometry>
    </collision>
    <inertial>
      <origin xyz="0.0216898313941301 -0.000872271219923791 -0.0116026222230294" rpy="0 0 0"/>
      <mass value="0.136250635109382"/>
      <inertia ixx="6.97372418737439e-05" ixy="1.7362293140102e-06" ixz="7.72200245787855e-06" iyy="5.5679349903428e-05" iyz="6.33305847996462e-07" izz="6.11792148050112e-05"/>
    </inertial>
  </link>

  <link name="upper_arm_link">
    <visual>
      <origin xyz="0 0 0" rpy="0 0 0"/>
      <geometry>
        <mesh filename="meshes/upper_arm_link.stl"/>
      </geometry>
      <material name="cad_grey"/>
    </visual>
    <collision>
      <origin xyz="0 0 0" rpy="0 0 0"/>
      <geometry>
        <mesh filename="meshes/upper_arm_link.stl"/>
      </geometry>
    </collision>
    <inertial>
      <origin xyz="0.0441477969675847 -8.44484394296047e-06 0.00791055059896283" rpy="0 0 0"/>
      <mass value="0.0827380990614375"/>
      <inertia ixx="1.42492853790166e-05" ixy="1.8047296268546e-10" ixz="-7.00193626203197e-06" iyy="0.000169030165174317" iyz="1.18551899069e-10" izz="0.000168612981312038"/>
    </inertial>
  </link>

  <link name="forearm_link">
    <visual>
      <origin xyz="0 0 0" rpy="0 0 0"/>
      <geometry>
        <mesh filename="meshes/forearm_link.stl"/>
      </geometry>
      <material name="cad_grey"/>
    </visual>
    <collision>
      <origin xyz="0 0 0" rpy="0 0 0"/>
      <geometry>
        <mesh filename="meshes/forearm_link.stl"/>
      </geometry>
    </collision>
    <inertial>
      <origin xyz="8.88597070924924e-10 -0.0508383452991497 -0.00545674801926912" rpy="0 0 0"/>
      <mass value="0.0294574375311473"/>
      <inertia ixx="3.10077246565589e-05" ixy="-1.61575988957095e-14" ixz="-3.14177560134728e-12" iyy="8.99272677070429e-06" iyz="6.9181222479369e-09" izz="2.40107466157349e-05"/>
    </inertial>
  </link>

  <link name="wrist_link">
    <visual>
      <origin xyz="0 0 0" rpy="0 0 0"/>
      <geometry>
        <mesh filename="meshes/wrist_link.stl"/>
      </geometry>
      <material name="cad_grey"/>
    </visual>
    <collision>
      <origin xyz="0 0 0" rpy="0 0 0"/>
      <geometry>
        <mesh filename="meshes/wrist_link.stl"/>
      </geometry>
    </collision>
    <inertial>
      <origin xyz="0.000452210654536336 0.00898859070235314 -0.00690941410614047" rpy="0 0 0"/>
      <mass value="0.0181766061397578"/>
      <inertia ixx="1.68299814445701e-06" ixy="4.56744756400051e-09" ixz="-3.19456415006301e-09" iyy="1.01953577809695e-06" iyz="-6.21306100109587e-08" izz="1.72788717301146e-06"/>
    </inertial>
  </link>

  <joint name="base_joint" type="revolute">
    <parent link="base_link"/>
    <child link="turret_link"/>
    <origin xyz="0 0 0.01365" rpy="2.1275 -1.5708 0"/>
    <axis xyz="1 0 0"/>
    <limit lower="-1.5708" upper="1.5708" effort="5" velocity="3"/>
  </joint>

  <joint name="shoulder_joint" type="revolute">
    <parent link="turret_link"/>
    <child link="upper_arm_link"/>
    <origin xyz="0.04225 0 0" rpy="0 0 1.0414"/>
    <axis xyz="0 0 1"/>
    <limit lower="-1.53" upper="0" effort="5" velocity="3"/>
  </joint>

  <joint name="elbow_joint" type="revolute">
    <parent link="upper_arm_link"/>
    <child link="forearm_link"/>
    <origin xyz="0.1452 -0.0001 0" rpy="3.1416 0 2.0591"/>
    <axis xyz="0 0 1"/>
    <limit lower="-3.075" upper="0.065" effort="5" velocity="3"/>
  </joint>

  <joint name="wrist_joint" type="revolute">
    <parent link="forearm_link"/>
    <child link="wrist_link"/>
    <origin xyz="0 -0.1 0" rpy="0 0.074136 2.2399"/>
    <axis xyz="0.074068 0 -0.99725"/>
    <limit lower="-2.9824" upper="0.1576" effort="5" velocity="3"/>
  </joint>

  <link name="camera_link">
    <inertial>
      <origin xyz="0 0 0" rpy="0 0 0"/>
      <mass value="0.000001"/>
      <inertia ixx="0.000000000001" ixy="0" ixz="0" iyy="0.000000000001" iyz="0" izz="0.000000000001"/>
    </inertial>
  </link>

  <joint name="camera_joint" type="fixed">
    <parent link="wrist_link"/>
    <child link="camera_link"/>
    <origin xyz="0.011 0.044 0.013" rpy="0 0 0"/>
  </joint>
</robot>
